Workbook

Sheet Totals
A3: Total conversations | B3: 13
A4: Completed conversations | B4: 13
A5: Successful conversations | B5: 11 | C5: =B5/B4 -> 0.84615385 | D5: P5 was rated as an unsuccessful interview due to a programming error throwing the conversation off track and thus excluded from futher analysis.
A6: Conversations in German | B6: 6 | D6: P9 was rated as unsuccessful due to the agent giving inappropriate responses based on the current step and hallucinating contexts and strategies, leading to a large number of failed steps
A7: Conversations in English | B7: 7
D8: P1 | E8: P2 | F8: P3 | G8: P4 | H8: P5 | I8: P6 | J8: P7 | K8: P8 | L8: P9 | M8: P10 | N8: P11 | O8: P12 | P8: P13
A9: Timings - all time measurements are given in hh:mm:ss format
A10: Time taken to complete conversations | D10: =(P1!S2) -> 0.028805451 | E10: =(P2!S2) -> 0.018909641 | F10: =(P3!S2) -> 0.023719468 | G10: =(P4!S2) -> 0.010753449 | H10: =(P5!S2) -> 0.10932016 | I10: =(P6!S2) -> 0.013694792 | J10: =(P7!S2) -> 11.919634 | K10: =(P8!S2) -> 0.010435417 | L10: =(P9!S2) -> 0.045933542 | M10: =(P10!S2) -> 3.1094405 | N10: =(P11!S2) -> 7.2110635 | O10: =(P12!S2) -> 11.362769 | P10: =(P13!S2) -> 3.2048686
A11: Active time (minus any periods where more than 15 minutes elapsed between messages) | D11: =(P1!S2) -> 0.028805451 | E11: =(P2!S2) -> 0.018909641 | F11: =(P3!S2) -> 0.023719468 | G11: =(P4!S2) -> 0.010753449 | H11: =(P5!S4) -> 0.063424583 | I11: =(P6!S2) -> 0.013694792 | J11: =(P7!S4) -> 0.017833715 | K11: =(P8!S2) -> 0.010435417 | L11: =(P9!S4) -> 0.033049363 | M11: =(P10!S4) -> 0.029550394 | N11: =(P11!S4) -> 0.010905567 | O11: =(P12!S4) -> 0.036996644 | P11: =(P13!S4) -> 0.020863854
A12: Longest time taken to complete | B12: =MAX(D10:G10,I10:K10,M10:P10) -> 11.919634
A13: Longest active time taken to complete | B13: =MAX(D11:G11,I11:K11,M11:P11) -> 0.036996644
A14: Shortest time taken to complete | B14: =MIN(D10:G10,I10:K10,M10:P10) -> 0.010435417
A15: Average time to complete | B15: =AVERAGE(D10:G10,I10:K10,M10:P10) -> 3.3558267
A16: Average active time to complete | B16: =AVERAGE(D11:G11,I11:K11,M11:P11) -> 0.020224399
A17: Median time to complete | B17: =MEDIAN(D10:G10,I10:K10,M10:P10) -> 0.028805451
A18: Median active time to complete | B18: =MEDIAN(D11:G11,I11:K11,M11:P11) -> 0.018909641
A20: Number of interactions resulting in errors (note: 1 fix applied while test in progress)
A21: Number of search results for 'ERROR' across app logs | B21: 17
A22: Number of search results for 'Invalid JSON' across app logs | B22: 122
A23: Number of search results for 'JSON is valid' across app logs | B23: 337
G24: Incorrect
A25: Total number of messages sent by agent | B25: {=SUM(COUNTIF(INDIRECT("'"&{"P1","P2","P3","P4","P6","P7","P8","P10","P11","P12","P13"}&"'!N7:N200"),"agent"))} -> 47918 | D25: Strategy step: | F25: =SUM(P1:P13!R2) -> 125 | G25: =(47/F25) -> 0.376
A26: Number of messages sent by users | B26: {=SUM(COUNTIF(INDIRECT("'"&{"P1","P2","P3","P4","P6","P7","P8","P10","P11","P12","P13"}&"'!N7:N200"),"user"))} -> 45784 | D26: Frequency step: | F26: =SUM(P1:P13!R3) -> 133 | G26: =(15/F26) -> 0.11278195
D27: "Complete" step: | F27: =SUM(P1:P13!R4) -> 40 | G27: =(17/F27) -> 0.425
A28: Rate of unexpected input received | B28: =1-(SUM(P1:P4!F2,P6:P8!F2,P10:P13!F2)/COUNTA(P1:P4!F2,P6:P8!F2,P10:P13!F2)) -> 0.10378104
A29: Success rate of handling unexpected input | B29: =SUM(P1:P4!G2,P7:P8!G2,P10:P13!G2)/COUNTA(P1:P4!G2,P7:P8!G2,P10:P13!G2) -> 0.68690476 | C29: Note: P6 did not have any unexpected input from the user so is excluded from this calculation
A31: Success rate of using appropriate degrees of formality and linguistic register | B31: =SUM(P1:P4!I2,P6:P8!I2,P10:P13!I2)/COUNTA(P1:P4!I2,P6:P8!I2,P10:P13!I2) -> 0.74086235
A33: Success rate of executing steps correctly | B33: =SUM(P1:P4!D2,P6:P8!D2,P10:P13!D2)/COUNTA(P1:P4!D2,P6:P8!D2,P10:P13!D2) -> 0.80371673 | C33: =SUM(P1:P13!D2)/COUNTA(P1:P13!D2) -> 0.73628849 | D33: =C33*247 -> 181.86326
A35: Success rate of classifying learning strategies like a human coder | B35: =SUM(P1:P4!C2,P6:P13!C2)/COUNTA(P1:P4!C2,P6:P13!C2) -> 0.47288037
A37: Success rate of responding to user mood and sentiment | B37: =SUM(P1:P4!L2,P6:P8!L2,P10:P13!L2)/COUNTA(P1:P4!L2,P6:P8!L2,P10:P13!L2) -> 0.76047538
A40: Percentage of user messages with tone ranked as 5 (very positive) | B40: =SUM(P1:P4!K6,P6:P8!K6,P10:P13!K6)/B26 -> 0
A41: Percentage of user messages with tone ranked as 4 (positive) | B41: =SUM(P1:P4!K5,P6:P8!K5,P10:P13!K5)/B26 -> 0.00013105015
A42: Percentage of user messages with tone ranked as 3 (neutral) | B42: =SUM(P1:P4!K4,P6:P8!K4,P10:P13!K4)/B26 -> 0.0049143806
A43: Percentage of user messages with tone ranked as 2 (negative) | B43: =SUM(P1:P4!K3,P6:P8!K3,P10:P13!K3)/B26 -> 0.00010920846
A44: Percentage of user messages with tone ranked as 1 (very negative) | B44: =SUM(P1:P4!K2,P6:P8!K2,P10:P13!K2)/B26 -> 0
B45: =SUM(B40:B44) -> 0.0051546392

Sheet ResponseTimes
A1: User message | B1: Agent response | C1: Difference (mm:ss.000) | E1: User message | F1: Latency between time message appears in Discord and logged in API logs
A2: 45581.385 | B2: 45581.385 | C2: =(B2-A2) -> 7.1053241e-05 | D2: =CEILING(C2,"00:00:05") -> 0.00011574074 | E2: I'm doing my masters degree in chemical engineering specifically in material sciences. I also did my bachelors in chemical engineering. | F2: Discord Time | G2: API log time
A3: 45581.39 | B3: 45581.39 | C3: =(B3-A3) -> 0.00016341435 | D3: =CEILING(C3,"00:00:05") -> 0.00017361111 | E3: I try to take a break where I go for a walk or read something, where I get out of the environment where I'm studying. Then I try to make a list for myself, prioritise some tasks and divide everything into smaller sections so it feels easier to tackle it. | F3: 45580.522 | G3: 45580.522 | H3: =ABS(G3-F3) -> 3.6111087e-06
A4: 45581.393 | B4: 45581.393 | C4: =(B4-A4) -> 8.2766204e-05 | D4: =CEILING(C4,"00:00:05") -> 0.00011574074 | E4: 3 | F4: 45579.753 | G4: 45579.753 | H4: =ABS(G4-F4) -> 1.2962992e-06
A5: 45581.398 | B5: 45581.398 | C5: =(B5-A5) -> 0.00015613426 | D5: =CEILING(C5,"00:00:05") -> 0.00017361111 | E5: I either try to do it on my own with what we learned during the course and then find some references to check if I was correct. Or I try to find someone who I know is more knowledgeable than me and ask them to explain the problem to me. | F5: 45579.753 | G5: 45579.753 | H5: =ABS(G5-F5) -> 3.3912002e-06
A6: 45581.399 | B6: 45581.399 | C6: =(B6-A6) -> 9.3009259e-05 | D6: =CEILING(C6,"00:00:05") -> 0.00011574074 | E6: 4 | F6: 45579.753 | G6: 45579.753 | H6: =ABS(G6-F6) -> 2.0138905e-06
A7: 45581.407 | B7: 45581.407 | C7: =(B7-A7) -> 9.3402778e-05 | D7: =CEILING(C7,"00:00:05") -> 0.00011574074 | E7: 4 | F7: 45579.753 | G7: 45579.753 | H7: =ABS(G7-F7) -> 3.5416597e-06
A8: 45581.407 | B8: 45581.407 | C8: =(B8-A8) -> 5.7638889e-05 | D8: =CEILING(C8,"00:00:05") -> 5.787037e-05 | E8: 3 | F8: 45579.753 | G8: 45579.753 | H8: =ABS(G8-F8) -> 2.1296291e-06
A9: 45581.409 | B9: 45581.409 | C9: =(B9-A9) -> 5.7881933e-05 | D9: =CEILING(C9,"00:00:05") -> 0.00011574074 | E9: Can you clarify for me what do you mean by 'methods' when writing a scientific paper? | F9: 45579.754 | G9: 45579.754 | H9: =ABS(G9-F9) -> 3.7268473e-06
A10: 45592.688 | B10: 45592.688 | C10: =(B10-A10) -> 0.00024592593 | D10: =CEILING(C10,"00:00:05") -> 0.00028935185 | E10: Before summarizing and explaining my own research, I always like to write about the already existing studies that I have read through and used as inspiration. For categorising these articles I use Mendeley plugin, because it makes things easier. After that I like to write out a table of contents with small explanations of every part and look it through if it's coherent. Than if I'm happy with it, I start to write out my findings that I already put into folders. I try to break down every method into different folders, so different results are easy to find. | F10: 45580.52 | G10: 45580.52 | H10: =ABS(G10-F10) -> 5.3472177e-06
A11: 45592.688 | B11: 45592.689 | C11: =(B11-A11) -> 0.00018209491 | D11: =CEILING(C11,"00:00:05") -> 0.00023148148 | E11: 4 | F11: 45580.52 | G11: 45580.52 | H11: =ABS(G11-F11) -> 1.3078752e-06
A12: 45592.689 | B12: 45592.689 | C12: =(B12-A12) -> 0.00021148148 | D12: =CEILING(C12,"00:00:05") -> 0.00023148148 | E12: 4 | F12: 45579.809 | G12: 45579.809 | H12: =ABS(G12-F12) -> 3.194451e-06
A13: 45592.689 | B13: 45592.69 | C13: =(B13-A13) -> 0.00013657407 | D13: =CEILING(C13,"00:00:05") -> 0.00017361111 | E13: 4 | F13: 45579.809 | G13: 45579.809 | H13: =ABS(G13-F13) -> 1.7129642e-06
A14: 45592.691 | B14: 45592.692 | C14: =(B14-A14) -> 0.0002774537 | D14: =CEILING(C14,"00:00:05") -> 0.00028935185 | E14: I usually write out notes on my iPad with a pen. If the professor provided the presentation notes before class, than I like to use that as a basis and supplement it with my own thoughts and the stuff that was said at the lecture.
A15: 45592.692 | B15: 45592.692 | C15: =(B15-A15) -> 0.00017731481 | D15: =CEILING(C15,"00:00:05") -> 0.00023148148 | E15: 3 | G15: Average difference: | H15: =AVERAGE(H3:H13) -> 2.843013e-06
A16: 45592.692 | B16: 45592.693 | C16: =(B16-A16) -> 0.00034048611 | D16: =CEILING(C16,"00:00:05") -> 0.00034722222 | E16: 3
A17: 45592.694 | B17: 45592.694 | C17: =(B17-A17) -> 0.00022505787 | D17: =CEILING(C17,"00:00:05") -> 0.00023148148 | E17: I like to read through my notes that I made for the exams as many times as I can, sometimes even out loud. If it's a very difficult exam than I like to try and explain it to some of my friends who might not know this subject, so I have to make things clear for them to understand. | F17: Response Time | G17: Number of messages | H17: Percentage of agent messages
A18: 45592.694 | B18: 45592.695 | C18: =(B18-A18) -> 0.00040253472 | D18: =CEILING(C18,"00:00:05") -> 0.00040509259 | E18: 4 | F18: Less than 3" | G18: =COUNTIFS(C:C,"<"&3/(24*60*60)) -> 1 | H18: =G18/(SUM(G18:G25)) -> 0.0037878788
A19: 45592.695 | B19: 45592.696 | C19: =(B19-A19) -> 0.00028726852 | D19: =CEILING(C19,"00:00:05") -> 0.00028935185 | E19: 2 | F19: 3" - <5" | G19: =COUNTIFS(C:C,">="&3/(24*60*60),C:C,"<"&5/(24*60*60)) -> 3 | H19: =G19/(SUM(G18:G25)) -> 0.011363636
A20: 45592.697 | B20: 45592.697 | C20: =(B20-A20) -> 9.7615741e-05 | D20: =CEILING(C20,"00:00:05") -> 0.00011574074 | E20: 2 | F20: 5" - <10" | G20: =COUNTIFS(C:C,">="&5/(24*60*60),C:C,"<"&10/(24*60*60)) -> 36 | H20: =G20/(SUM(G18:G25)) -> 0.13636364
A21: 45592.699 | B21: 45592.7 | C21: =(B21-A21) -> 0.00018101852 | D21: =CEILING(C21,"00:00:05") -> 0.00023148148 | E21: Using the textbook written about the subject, if it exists and using mostly the notes provided by the professors. I like using my own notes because I already wrote things in a way I will understand it. If it's necessary than I will look for more online sources maybe videos explaining the subject. | F21: 10" - <15" | G21: =COUNTIFS(C:C,">="&10/(24*60*60),C:C,"<"&15/(24*60*60)) -> 81 | H21: =G21/(SUM(G18:G25)) -> 0.30681818
A22: 45592.7 | B22: 45592.701 | C22: =(B22-A22) -> 9.2719907e-05 | D22: =CEILING(C22,"00:00:05") -> 0.00011574074 | E22: 4 | F22: 15" - <20" | G22: =COUNTIFS(C:C,">="&15/(24*60*60),C:C,"<"&20/(24*60*60)) -> 62 | H22: =G22/(SUM(G19:G26)) -> 0.23574124
A23: 45592.701 | B23: 45592.701 | C23: =(B23-A23) -> 0.00019023148 | D23: =CEILING(C23,"00:00:05") -> 0.00023148148 | E23: 4 | F23: 20" - <30" | G23: =COUNTIFS(C:C,">="&20/(24*60*60),C:C,"<"&30/(24*60*60)) -> 49 | H23: =G23/(SUM(G19:G26)) -> 0.18631163
A24: 45592.704 | B24: 45592.704 | C24: =(B24-A24) -> 0.00027148148 | D24: =CEILING(C24,"00:00:05") -> 0.00028935185 | E24: I found that the Pomodoro technique works great for me when I have to review my notes. When I have to write papers I tend to forget about time. But I definitely would like improve my motivation in general and find strategies that I can implement to reduce my procastination. | F24: 30" - <1' | G24: =COUNTIFS(C:C,">="&30/(24*60*60),C:C,"<"&60/(24*60*60)) -> 26 | H24: =G24/(SUM(G18:G25)) -> 0.098484848
A25: 45592.706 | B25: 45592.706 | C25: =(B25-A25) -> 0.00026112269 | D25: =CEILING(C25,"00:00:05") -> 0.00028935185 | E25: I really like the 5-second rule, I will definitely try to implement it in the future when I feel the procastination coming in or when I have no motivation. | F25: 1' or more | G25: =COUNTIFS(C:C,">="&60/(24*60*60)) -> 6 | H25: =G25/(SUM(G18:G25)) -> 0.022727273
D26: =CEILING(C26,"00:00:05") -> 0 | F26: Average | G26: =AVERAGE(C:C) -> 0.00022439333
A27: 2024-10-17 11:36:16,072 | B27: 2024-10-17 11:36:28,419 | C27: =(B27-A27) -> 0.00014290509 | D27: =CEILING(C27,"00:00:05") -> 0.00017361111 | E27: In Psychologie, Bachelor of Science | F27: Total | G27: =SUM(G18:G25) -> 264
A28: 45582.487 | B28: 45582.487 | C28: =(B28-A28) -> 0.00058590278 | D28: =CEILING(C28,"00:00:05") -> 0.00063657407 | E28: Ja gerne. Nachdem ich weiß, was die Vision und das Ziel ist, und ich meine wissenschafliche Arbeit durchgeführt habe und un den Bericht verfassen muss, gehe ich so vor, dass ich zunächst das Abstract schreibe. Dadurch weiß ich, ob ich meine Arbeit gut darstellen kann. Anschließend fange ich damit an die ganze Arbeit strukturell aufzubauen und zu entscheiden, welche Kapitel ich brauche. Dann fange ich an mit dem Outlining meiner Arbeit und setze bereits wichtige Tabellen und Bilder in meine Arbeit ein. Darin schreibe ich überall punktuell rein, was ich dem Leser über meine Arbeit berichten möchte. Dieses Outline verfeinere ich immer wieder, bis ich zufrieden bin. Anschließend arbeite ich jeden Punkt aus, und entwickle ganze Sätze. Die Sätze sind noch sehr grob und enthalten fehler. Allerdings schreibe ich zügig und verfeinere die Sprache dann zum Schluss. Final zeige ich Kollegen meine Arbeit und hole mir Feedback dazu ein. Das mache ich immer weiter, bis keine Kritik mehr vorhanden ist. Dann reiche ich meine Arbeit fristgerecht ein.
A29: 45582.488 | B29: 45582.488 | C29: =(B29-A29) -> 0.00032418981 | D29: =CEILING(C29,"00:00:05") -> 0.00034722222 | E29: Ich verwende sie meistens, also 4. Ich bin bereits eingeübt in dieser Prozedur und habe gute Ergebnisse erzielt. Ich denke, ich werde immer noch etwas besser und würde es beibehalten. | F29: Difference (mm:ss.000) | G29: Frequency
A30: 45582.491 | B30: 45582.491 | C30: =(B30-A30) -> 0.00028258102 | D30: =CEILING(C30,"00:00:05") -> 0.00028935185 | E30: Selbsterkärungen nutze ich auch meistens (4). Häufig mache ich mir dazu vorher Concept Maps am Whiteboard, oder Mindmaps auf dem Papier. Dann gehe ich diese durch Selbstgespräche durch und versuche mich zu hinterfragen, ob ich nicht etwas falsch sehe, oder übersehen habe. Wenn ich garnicht weiter komme, mache ich ein Miro Board auf, was digital ist. Darin mache ich ein sogenanntes Question Storming und sammele lediglich Fragen die mir bezüglich meiner Arbeit in den Sinn kommen. Dafür nehme ich mir mehrere Stunden. Anschließend versuche ich die Fragen zu strukturieren und als Anhaltspunkte zu nutzen, um weitere Recherchen durchzuführen. Das Fragenstellen ist führt meistens zu kritischen Fragen die mir dabei helfen, weitere Erklärungen zu finden. Die Erklärungen schreibe ich dann auch als Postits in das Miro. | F30: 3.2037037e-05 | G30: 1
A31: 45582.493 | B31: 45582.494 | C31: =(B31-A31) -> 0.00080571759 | D31: =CEILING(C31,"00:00:05") -> 0.00081018519 | E31: Ja, in der Regel sind die wissenschaftlichen Arbeiten bei uns in der Psychologie nach einem gewissen Schema aufgebaut, an dem sich alle Studierenden orientieren. Darunter gehört Einführung, Methodik, Auswertung und Resultate, sowie Limitationen und Diskussionen. Dabei versuche ich immer für den Leser eine Art Story aufzubauen und einen roten Pfaden mitzugeben. Wenn ich merke, dass manche Bereiche zu groß sind, versuche ich diese noch mal aufzuteilen. In letzter Zeit schreibe ich aber auch schon bei Resultaten kleinere Diskussionen und Limitationen, damit der Leser nicht erst zu spät am Ende des Berichts damit konfrontiert wird. Also ich muss garnicht sosehr selbst entscheiden, welche Kapitel es gibt. | F31: 3.7974537e-05 | G31: 1
A32: 45582.495 | B32: 45582.495 | C32: =(B32-A32) -> 0.00037457176 | D32: =CEILING(C32,"00:00:05") -> 0.00040509259 | E32: Ich habe diese meistens verwendet. Aber ich glaube du hast dich mit deinem Feedback wiederholt und bist nicht auf meine letzte Nachricht eingegangen. Wie sollen wir weiter verfahren? | F32: 3.8935197e-05 | G32: 1
A33: 45582.496 | B33: 45582.496 | C33: =(B33-A33) -> 0.00031040509 | D33: =CEILING(C33,"00:00:05") -> 0.00034722222 | E33: Durch das Outlining kann ich mir sehr gut überlegen, wie ich meine Geschichte erzählen will und welche Dinge ich hervorhebe und auf was ich hinweisen möchte. Da alles in dieser Phase noch stark komprimiert ist, habe ich einen guten Überblick und kann kritisch hinterfragen, ob der Rote Pfaden ersichtlich ist. | F33: 5.7638889e-05 | G33: 1
A34: 45582.497 | B34: 45582.497 | C34: =(B34-A34) -> 0.0003478588 | D34: =CEILING(C34,"00:00:05") -> 0.00040509259 | E34: Bei mündlichen und schriftlichen Prüfungen verwende ich diese Strategie nie, also 1 | F34: 5.7881933e-05 | G34: 1
A35: 45582.497 | B35: 45582.498 | C35: =(B35-A35) -> 0.00030030093 | D35: =CEILING(C35,"00:00:05") -> 0.00034722222 | E35: Sehr oft, also 4 | F35: 6.4363426e-05 | G35: 1
A36: 45582.499 | B36: 45582.5 | C36: =(B36-A36) -> 0.0004424537 | D36: =CEILING(C36,"00:00:05") -> 0.00046296296 | E36: Bei schwierigen Texten, nehme ich mir mehr Zeit. Manchmal mache ich auch eine Pause um mich zu erholen, da mir vielleicht nur gerade die Energie fehlt, den Text zu verarbeiten. Wenn der Text immer noch schwierig ist, schreibe ich mir eine eigenen Erklärungstext, worin ich die Inhalte stück für stück auseinander nehne und jeden Teil versuche einzeln zu verstehen, bevor ich das ganze verstehe. Sollte es garnicht klappen, nutze ich chatgpt und frage, was der Autor mir mit dem Text wahrscheinlich sagen möchte, aber das passiert sehr selten. | F36: 6.5925926e-05 | G36: 1
A37: 45582.5 | B37: 45582.501 | C37: =(B37-A37) -> 0.0003944213 | D37: =CEILING(C37,"00:00:05") -> 0.00040509259 | E37: 4 | F37: 7.1053241e-05 | G37: 1
A38: 45582.501 | B38: 45582.501 | C38: =(B38-A38) -> 9.5879618e-05 | D38: =CEILING(C38,"00:00:05") -> 0.00011574074 | E38: Manchmal | F38: 7.2002303e-05 | G38: 1
A39: 45582.502 | B39: 45582.502 | C39: =(B39-A39) -> 0.00015277778 | D39: =CEILING(C39,"00:00:05") -> 0.00017361111 | E39: Ich nutze Notion.so, eine Online App worin ich für jedes Studienfach eine eigene Seite anlege. Darin lege ich dann Tabellen an wo jede Zeile ein Konzept ist. Darin bearbeite ich dann die Lerninhalte und habe immer eine Übersicht über meinen Fortschritt | F39: 7.4872685e-05 | G39: 1
A40: 45582.502 | B40: 45582.502 | C40: =(B40-A40) -> 0.00031177083 | D40: =CEILING(C40,"00:00:05") -> 0.00034722222 | E40: immer | F40: 7.8136574e-05 | G40: 1
...

Sheet SurveyResults
A1: See below for key to question codes. Incomplete responses have been excluded from analysis. | G1: Cells highlighted in blue contain responses from pilot evaluation survey
A2: id. Response ID | B2: submitdate. Date submitted | C2: lastpage. Last page | D2: startlanguage. Start language | E2: seed. Seed | F2: startdate. Date started | G2: datestamp. Date last action | H2: BUS[SQ001] | I2: BUS[SQ002] | J2: BUS[SQ003] | K2: BUS[SQ004] | L2: BUS[SQ005] | M2: BUS[SQ006] | N2: BUS[SQ007] | O2: BUS[SQ008] | P2: BUS[SQ009] | Q2: BUS[SQ010] | R2: StrategyAccuracy | S2: StrategyReflection | T2: ChatbotFamiliarity | U2: LlmUse | V2: Age | W2: Nationality | X2: Edu | Y2: CurrentEdu | Z2: Grade | AA2: Gender
A3: 2 | B3: 2024-10-17 12:27:23 | C3: 4 | D3: en | E3: 1885224814 | F3: 2024-10-17 12:25:46 | G3: 2024-10-17 12:27:23 | H3: 5 | I3: 5 | J3: 5 | K3: 5 | L3: 5 | M3: 5 | N3: 5 | O3: 5 | P3: 5 | Q3: 5 | R3: 5 | S3: Yes, it highlighted that I only use study techniques by myself and that I could benefit from having group study sessions and online tutorials to supplement my studies. | T3: 5 | U3: 1 | V3: 31 | W3: British | X3: BSc/Undergraduate | Y3: MSc/Masters | Z3: Not known | AA3: Female
A4: 3 | B4: 2024-10-17 14:37:19 | C4: 4 | D4: de | E4: 1992059185 | F4: 2024-10-17 14:33:34 | G4: 2024-10-17 14:37:19 | H4: 5 | I4: 5 | J4: 5 | K4: 4 | L4: 5 | M4: 3 | N4: 4 | O4: 2 | P4: 4 | Q4: 3 | R4: 5 | S4: Der Chatbot hat mir mehrere Strategien aufgelistet, von denen ich bereits alle bis auf einen "Lerngruppen" häufig nutze. Also sehr viel weiter hat mir der Chatbot dann nicht mehr geholfen oder mir neue, kreative Strategien vorgeschlagen. Der Chatbot hätte mir z.B. aufgrund meiner guten Lernstrategien noch "Learning by teaching" empfehlen können, hat er aber nicht getan. Es gibt sicher noch mehr, was der Chatbot wissen könnte, um auch High achiever im Studium besser einzugehen | T4: 5 | U4: 4 | V4: 34 | W4: deutsch | X4: Master | Y4: Bachelor of Science Psychologie | AA4: Male
A5: 4 | B5: 2024-10-17 18:26:44 | C5: 4 | D5: de | E5: 1827158114 | F5: 2024-10-17 18:25:48 | G5: 2024-10-17 18:26:43 | H5: 5 | I5: 5 | J5: 5 | K5: 5 | L5: 5 | M5: 5 | N5: 5 | O5: 5 | P5: 5 | Q5: 5 | R5: 5 | S5: - | T5: 5 | U5: 3 | V5: 24 | W5: deutsch | X5: Master | Y5: - | Z5: 1,4 | AA5: Male
A6: 5 | B6: 2024-10-18 11:48:04 | C6: 4 | D6: de | E6: 1723420554 | F6: 2024-10-18 11:45:49 | G6: 2024-10-18 11:48:04 | H6: 5 | I6: 5 | J6: 4 | K6: 4 | L6: 4 | M6: 5 | N6: 4 | O6: 5 | P6: 5 | Q6: 4 | R6: 4 | S6: Bis auf eine Nachfrage zu einer Strategie, die ignoriert wurde war das Gespräch gut und auch hilfreich nochmal Strategie zu sprechen und ob/wie es ausgereift werden kann | T6: 5 | U6: 3 | V6: 25 | W6: deutsch | X6: Bachelor | Y6: Master (und Bachelor) | Z6: - | AA6: Female
A7: 6 | B7: 2024-10-20 21:47:40 | C7: 4 | D7: en | E7: 1934991090 | F7: 2024-10-20 21:44:41 | G7: 2024-10-20 21:47:40 | H7: 1 | I7: 1 | J7: 1 | K7: 1 | L7: 1 | M7: 2 | N7: 2 | O7: 1 | P7: 1 | Q7: 1 | R7: 2 | S7: I got a summary of what ive written to the chatbot and about two recommendations (finding a tutor or an online class) if i was struggling | T7: 3 | U7: 2 | V7: 20 | W7: czech | X7: high school | Y7: bachelors | AA7: Female
A8: 9 | B8: 2024-10-26 15:15:16 | C8: 4 | D8: en | E8: 945976960 | F8: 2024-10-26 15:01:07 | G8: 2024-10-26 15:15:16 | H8: 4 | I8: 5 | J8: 3 | K8: 4 | L8: 5 | M8: 4 | N8: 3 | O8: 3 | P8: 3 | Q8: 3 | R8: 3 | S8: Actually no, I think the suggestions that chat bot gave in the last message were so general and not really related to my needs. It also would be better to explain suggestions deeper instead of just explaning with one sentence. | T8: 4 | U8: 5 | V8: 19 | W8: Turkey | X8: Highschool | Y8: Bachelor | Z8: 1.8(1 ist best, 6 is worst) | AA8: Male
A9: 10 | B9: 2024-10-27 16:30:10 | C9: 4 | D9: de | E9: 761253156 | F9: 2024-10-27 16:22:18 | G9: 2024-10-27 16:30:10 | H9: 4 | I9: 5 | J9: 4 | K9: 5 | L9: 4 | M9: 4 | N9: 5 | O9: 4 | P9: 4 | Q9: 3 | R9: 4 | S9: Der Chatbot hat mir ein paar neue Strategien zum Ausprobieren vorgeschlagen, z.B. ein Ritual vor dem Lernen, um mich darauf einzustimmen und zu motivieren. Auf Nachfrage kamen noch mehr Vorschläge. | T9: 1 | U9: 1 | V9: 30 | W9: Deutsch | X9: Berufsausbildung | Y9: Fachweiterbildung | Z9: 2 | AA9: Female
A10: 12 | B10: 2024-10-27 19:17:07 | C10: 4 | D10: en | E10: 2035673428 | F10: 2024-10-27 19:10:42 | G10: 2024-10-27 19:17:07 | H10: 4 | I10: 4 | J10: 4 | K10: 4 | L10: 4 | M10: 3 | N10: 3 | O10: 3 | P10: 3 | Q10: 4 | R10: 4 | S10: Yes It made me recognise the strategies I use and benefits of this e.g. organising and transforming It discussed elaboration techniques which was an interesting point that I use less regularly | T10: 2 | U10: 2 | V10: 27 | W10: British | X10: Masters | Y10: Masters | Z10: Distinction | AA10: Female
A11: 15 | B11: 2024-10-28 16:17:19 | C11: 4 | D11: en | E11: 1839618646 | F11: 2024-10-28 16:14:10 | G11: 2024-10-28 16:17:19 | H11: 5 | I11: 5 | J11: 5 | K11: 4 | L11: 4 | M11: 4 | N11: 4 | O11: 4 | P11: 4 | Q11: 5 | R11: 5 | S11: I think the strategies that the bot mentioned in the final message were a summary of what was said before so it did not really make me think any further | T11: 3 | U11: 3 | V11: 23 | W11: Finnish | X11: Bachelor's degree | Y11: Master's degree | Z11: 4 (on a scale of 1-5 where 1 is the first passing grade and 5 is the best) | AA11: Female
A12: 17 | B12: 2024-10-29 12:27:17 | C12: 4 | D12: en | E12: 1098243403 | F12: 2024-10-29 11:53:07 | G12: 2024-10-29 12:27:17 | H12: 5 | I12: 5 | J12: 5 | K12: 4 | L12: 5 | M12: 4 | N12: 4 | O12: 4 | P12: 5 | Q12: 4 | R12: 4 | S12: I feel like my chat with the studybot was very thought provoking as I had to look through the list it compiled about my studying habits. To be honest I usually don’t think about the habits or methods I use, I just do them. So it was nice to “hear” that they are actually working methods. And I also got some pointers and ideas on how to stop or prevent procrastination. | T12: 4 | U12: 3 | V12: 25 | W12: Hungarian | X12: Bachelor’s degree at university | Y12: Master’s degree | AA12: Female
A13: 1 | B13: 2024-09-02 20:25:18 | C13: 4 | D13: en | E13: 1359551649 | F13: 2024-09-02 20:22:33 | G13: 2024-09-02 20:25:18 | H13: 3 | I13: 5 | J13: 3 | K13: 3 | L13: 4 | M13: 4 | N13: 4 | O13: 4 | P13: 3 | Q13: 5 | R13: 4 | S13: It summarizes what I do into “methodology” which is much more accurate than me saying I do this and that | T13: 4 | U13: 3 | V13: 21 | W13: Chinese | X13: High school | Y13: Bachelor last year | Z13: B | AA13: Female
A14: 2 | B14: 2024-09-03 21:12:24 | C14: 4 | D14: de | E14: 1453328173 | F14: 2024-09-03 21:10:25 | G14: 2024-09-03 21:12:24 | H14: 5 | I14: 5 | J14: 5 | K14: 5 | L14: 5 | M14: 5 | N14: 5 | O14: 5 | P14: 5 | Q14: 5 | R14: 5 | S14: Ja, kann mich leider nicht mehr erinnern | T14: 4 | U14: 5 | V14: 23 | W14: Österreich | X14: Matura | Y14: Bachelor | Z14: 3 | AA14: Female
A15: 3 | B15: 2024-09-17 15:08:01 | C15: 4 | D15: de | E15: 1036014866 | F15: 2024-09-17 14:58:28 | G15: 2024-09-17 15:08:01 | H15: 5 | I15: 4 | J15: 4 | K15: 4 | L15: 5 | M15: 5 | N15: 4 | O15: 5 | P15: 5 | Q15: 3 | R15: 5 | S15: Nein, es wurde nur das zusammen gefasst, das ich gesagt habe, aber keine neuen Anregungen gegeben. | T15: 4 | U15: 3 | V15: 43 | W15: Deutsch | X15: Staatlich geprüfter Betriebswirt | Y15: Bachelor Wirtschaftsinformatik | Z15: 2 | AA15: Female
H17: The chatbot function was easily detectable | I17: It was easy to find the chatbot | J17: Communicating with the chatbot was clear | K17: The chatbot was able to keep track of context | L17: The chatbot’s responses were easy to understand | M17: I find that the chatbot understands what I want and helps me achieve my goal | N17: The chatbot gives me the appropriate amount of information | O17: The chatbot only gives me the information I need | P17: I feel like the chatbot’s responses were accurate | Q17: My waiting time for a response from the chatbot was short | R17: Do you think the chatbot accurately recognised and summarised the strategies you mentioned? | T17: How familiar are you with chatbots and/or other conversational interfaces? | U17: How frequently do you use AI/Large Language Models (LLM) for work or education?
G18: Strongly Agree (Daily) | H18: =COUNTIF(H3:H15, 5) -> 8 | I18: =COUNTIF(I3:I15, 5) -> 10 | J18: =COUNTIF(J3:J15, 5) -> 6 | K18: =COUNTIF(K3:K15, 5) -> 4 | L18: =COUNTIF(L3:L15, 5) -> 7 | M18: =COUNTIF(M3:M15, 5) -> 5 | N18: =COUNTIF(N3:N15, 5) -> 4 | O18: =COUNTIF(O3:O15, 5) -> 5 | ... R18: =COUNTIF(R3:R15, 5) -> 6 | T18: =COUNTIF(T3:T15, 5) -> 4 | U18: =COUNTIF(U3:U15, 5) -> 2
G19: Agree (Very Often) | H19: =COUNTIF(H3:H15, 4) -> 3 | I19: =COUNTIF(I3:I15, 4) -> 2 | J19: =COUNTIF(J3:J15, 4) -> 4 | K19: =COUNTIF(K3:K15, 4) -> 7 | L19: =COUNTIF(L3:L15, 4) -> 5 | M19: =COUNTIF(M3:M15, 4) -> 5 | N19: =COUNTIF(N3:N15, 4) -> 6 | O19: =COUNTIF(O3:O15, 4) -> 4 | ... R19: =COUNTIF(R3:R15, 4) -> 5 | T19: =COUNTIF(T3:T15, 4) -> 5 | U19: =COUNTIF(U3:U15, 4) -> 1
G20: No opinion (Sometimes) | H20: =COUNTIF(H3:H15, 3) -> 1 | I20: =COUNTIF(I3:I15, 3) -> 0 | J20: =COUNTIF(J3:J15, 3) -> 2 | K20: =COUNTIF(K3:K15, 3) -> 1 | L20: =COUNTIF(L3:L15, 3) -> 0 | M20: =COUNTIF(M3:M15, 3) -> 2 | N20: =COUNTIF(N3:N15, 3) -> 2 | O20: =COUNTIF(O3:O15, 3) -> 2 | ... R20: =COUNTIF(R3:R15, 3) -> 1 | T20: =COUNTIF(T3:T15, 3) -> 2 | U20: =COUNTIF(U3:U15, 3) -> 6
G21: Disagree (Rarely) | H21: =COUNTIF(H3:H15, 2) -> 0 | I21: =COUNTIF(I3:I15, 2) -> 0 | J21: =COUNTIF(J3:J15, 2) -> 0 | K21: =COUNTIF(K3:K15, 2) -> 0 | L21: =COUNTIF(L3:L15, 2) -> 0 | M21: =COUNTIF(M3:M15, 2) -> 1 | N21: =COUNTIF(N3:N15, 2) -> 1 | O21: =COUNTIF(O3:O15, 2) -> 1 | ... R21: =COUNTIF(R3:R15, 2) -> 1 | T21: =COUNTIF(T3:T15, 2) -> 1 | U21: =COUNTIF(U3:U15, 2) -> 2
G22: Strongly Disagree (Never) | H22: =COUNTIF(H3:H15, 1) -> 1 | I22: =COUNTIF(I3:I15, 1) -> 1 | J22: =COUNTIF(J3:J15, 1) -> 1 | K22: =COUNTIF(K3:K15, 1) -> 1 | L22: =COUNTIF(L3:L15, 1) -> 1 | M22: =COUNTIF(M3:M15, 1) -> 0 | N22: =COUNTIF(N3:N15, 1) -> 0 | O22: =COUNTIF(O3:O15, 1) -> 1 | ... R22: =COUNTIF(R3:R15, 1) -> 0 | T22: =COUNTIF(T3:T15, 1) -> 1 | U22: =COUNTIF(U3:U15, 1) -> 2
G23: Total | H23: =SUM(H18:H22) -> 13 | I23: =SUM(I18:I22) -> 13 | J23: =SUM(J18:J22) -> 13 | K23: =SUM(K18:K22) -> 13 | L23: =SUM(L18:L22) -> 13 | M23: =SUM(M18:M22) -> 13 | N23: =SUM(N18:N22) -> 13 | O23: =SUM(O18:O22) -> 13 | ... R23: =SUM(R18:R22) -> 13
G24: Min | H24: 5 | I24: 5 | J24: 5 | K24: 5 | L24: 5 | M24: 5 | N24: 5 | O24: 5 | P24: 5 | Q24: 5 | R24: 5
G25: Max | H25: 1 | I25: 1 | J25: 1 | K25: 1 | L25: 1 | M25: 2 | N25: 2 | O25: 1 | P25: 1 | Q25: 1 | R25: 2
G26: Mean | H26: =(SUM(H18*5,H19*4,H20*3,H21*2,H22*1)/H23) -> 4.3076923 | I26: =(SUM(I18*5,I19*4,I20*3,I21*2,I22*1)/I23) -> 4.5384615 | J26: =(SUM(J18*5,J19*4,J20*3,J21*2,J22*1)/J23) -> 4.0769231 | K26: =(SUM(K18*5,K19*4,K20*3,K21*2,K22*1)/K23) -> 4 | L26: =(SUM(L18*5,L19*4,L20*3,L21*2,L22*1)/L23) -> 4.3076923 | M26: =(SUM(M18*5,M19*4,M20*3,M21*2,M22*1)/M23) -> 4.0769231 | N26: =(SUM(N18*5,N19*4,N20*3,N21*2,N22*1)/N23) -> 4 | O26: =(SUM(O18*5,O19*4,O20*3,O21*2,O22*1)/O23) -> 3.8461538 | ... R26: =(SUM(R18*5,R19*4,R20*3,R21*2,R22*1)/R23) -> 4.2307692
G27: Mean2 | H27: =(SUM(H18*25,H19*16,H20*9,H21*4,H22*1)/H23) -> 19.846154 | I27: =(SUM(I18*25,I19*16,I20*9,I21*4,I22*1)/I23) -> 21.769231 | J27: =(SUM(J18*25,J19*16,J20*9,J21*4,J22*1)/J23) -> 17.923077 | K27: =(SUM(K18*25,K19*16,K20*9,K21*4,K22*1)/K23) -> 17.076923 | L27: =(SUM(L18*25,L19*16,L20*9,L21*4,L22*1)/L23) -> 19.692308 | M27: =(SUM(M18*25,M19*16,M20*9,M21*4,M22*1)/M23) -> 17.461538 | N27: =(SUM(N18*25,N19*16,N20*9,N21*4,N22*1)/N23) -> 16.769231 | O27: =(SUM(O18*25,O19*16,O20*9,O21*4,O22*1)/O23) -> 16.307692 | ... R27: =(SUM(R18*25,R19*16,R20*9,R21*4,R22*1)/R23) -> 18.692308
G28: Standard Deviation | H28: =SQRT(H27-H26) -> 3.9418855 | I28: =SQRT(I27-I26) -> 4.1509962 | J28: =SQRT(J27-J26) -> 3.721042 | K28: =SQRT(K27-K26) -> 3.6162029 | L28: =SQRT(L27-L26) -> 3.9223227 | M28: =SQRT(M27-M26) -> 3.6584991 | N28: =SQRT(N27-N26) -> 3.573406 | O28: =SQRT(O27-O26) -> 3.5300904 | ... R28: =SQRT(R27-R26) -> 3.802833
A30: Question codes:
A31: BUS[SQ001]. Please indicate your level of agreement with the following statements. (1) Strongly disagree - (5) Strongly agree [The chatbot function was easily detectable]
A32: BUS[SQ002]. Please indicate your level of agreement with the following statements. (1) Strongly disagree - (5) Strongly agree [It was easy to find the chatbot]
A33: BUS[SQ003]. Please indicate your level of agreement with the following statements. (1) Strongly disagree - (5) Strongly agree [Communicating with the chatbot was clear]
A34: BUS[SQ004]. Please indicate your level of agreement with the following statements. (1) Strongly disagree - (5) Strongly agree [The chatbot was able to keep track of context]
A35: BUS[SQ005]. Please indicate your level of agreement with the following statements. (1) Strongly disagree - (5) Strongly agree [The chatbot’s responses were easy to understand]
A36: BUS[SQ006]. Please indicate your level of agreement with the following statements. (1) Strongly disagree - (5) Strongly agree [I find that the chatbot understands what I want and helps me achieve my goal]
A37: BUS[SQ007]. Please indicate your level of agreement with the following statements. (1) Strongly disagree - (5) Strongly agree [The chatbot gives me the appropriate amount of information]
A38: BUS[SQ008]. Please indicate your level of agreement with the following statements. (1) Strongly disagree - (5) Strongly agree [The chatbot only gives me the information I need]
A39: BUS[SQ009]. Please indicate your level of agreement with the following statements. (1) Strongly disagree - (5) Strongly agree [I feel like the chatbot’s responses were accurate]
A40: BUS[SQ010]. Please indicate your level of agreement with the following statements. (1) Strongly disagree - (5) Strongly agree [My waiting time for a response from the chatbot was short]
A42: StrategyAccuracy. In the last message, you received feedback about your learning strategies. Do you think the chatbot accurately recognised and summarised the strategies you mentioned? (1) Strongly disagree - (5) Strongly agree
... A51: Gender. What gender do you identify as?

Sheet StrategyEvaluations
A1: strategy | B1: SU | C1: SF | D1: SC | E1: SU | F1: SF | G1: SC | H1: SU | I1: SF | J1: SC | K1: SU | L1: SF | M1: SC | N1: SU | O1: SF | P1: SC | Q1: SU | R1: SF | S1: SC | T1: SU | U1: SF | V1: SC | W1: SU | X1: SF | Y1: SC | Z1: SU | AA1: SF | AB1: SC | AC1: SU | AD1: SF | AE1: SC | AF1: SU | AG1: SF | AH1: SC | AI1: SU | AJ1: SF | AK1: SC | AL1: SU | AM1: SF | AN1: SC
B2: P1 | E2: P2 | H2: P3 | K2: P4 | N2: P5 | Q2: P6 | T2: P7 | W2: P8 | Z2: P9 | AC2: P10 | AF2: P11 | AI2: P12 | AL2: P13
A3: 001-001 | B3: =FALSE() -> FALSE | C3: 0 | D3: 0 | E3: =TRUE() -> TRUE | F3: 1 | G3: 3 | H3: =FALSE() -> FALSE | I3: 0 | J3: 0 | K3: =FALSE() -> FALSE | L3: 0 | M3: 0 | N3: =FALSE() -> FALSE | O3: 0 | P3: 0 | Q3: =TRUE() -> TRUE | R3: 1 | S3: 3 | T3: =TRUE() -> TRUE | U3: 1 | V3: 3 | W3: =FALSE() -> FALSE | X3: 0 | Y3: 0 | Z3: =TRUE() -> TRUE | AA3: 1 | AB3: 2 | AC3: =TRUE() -> TRUE | AD3: 1 | AE3: 2 | AF3: =FALSE() -> FALSE | AG3: 0 | AH3: 0 | AI3: =TRUE() -> TRUE | AJ3: 1 | AK3: 4 | AL3: =TRUE() -> TRUE | AM3: 1 | AN3: 4
A4: 001-002 | B4: =FALSE() -> FALSE | C4: 0 | D4: 0 | E4: =FALSE() -> FALSE | F4: 0 | G4: 0 | H4: =TRUE() -> TRUE | I4: 1 | J4: 4 | K4: =TRUE() -> TRUE | L4: 2 | M4: 7 | N4: =FALSE() -> FALSE | O4: 0 | P4: 0 | Q4: =TRUE() -> TRUE | R4: 1 | S4: 2 | T4: =TRUE() -> TRUE | U4: 2 | V4: 5 | W4: =FALSE() -> FALSE | X4: 0 | Y4: 0 | Z4: =FALSE() -> FALSE | AA4: 0 | AB4: 0 | AC4: =TRUE() -> TRUE | AD4: 2 | AE4: 3 | AF4: =TRUE() -> TRUE | AG4: 1 | AH4: 4 | AI4: =FALSE() -> FALSE | AJ4: 0 | AK4: 0 | AL4: =TRUE() -> TRUE | AM4: 1 | AN4: 2
A5: 002-001 | B5: =FALSE() -> FALSE | C5: 0 | D5: 0 | E5: =TRUE() -> TRUE | F5: 1 | G5: 1 | H5: =FALSE() -> FALSE | I5: 0 | J5: 0 | K5: =FALSE() -> FALSE | L5: 0 | M5: 0 | N5: =FALSE() -> FALSE | O5: 0 | P5: 0 | Q5: =FALSE() -> FALSE | R5: 0 | S5: 0 | T5: =FALSE() -> FALSE | U5: 0 | V5: 0 | W5: =TRUE() -> TRUE | X5: 1 | Y5: 2 | Z5: =FALSE() -> FALSE | AA5: 0 | AB5: 0 | AC5: =FALSE() -> FALSE | AD5: 0 | AE5: 0 | AF5: =FALSE() -> FALSE | AG5: 0 | AH5: 0 | AI5: =FALSE() -> FALSE | AJ5: 0 | AK5: 0 | AL5: =FALSE() -> FALSE | AM5: 0 | AN5: 0
A6: 003-001 | B6: =FALSE() -> FALSE | C6: 0 | D6: 0 | E6: =FALSE() -> FALSE | F6: 0 | G6: 0 | H6: =TRUE() -> TRUE | I6: 2 | J6: 8 | K6: =FALSE() -> FALSE | L6: 0 | M6: 0 | N6: =FALSE() -> FALSE | O6: 0 | P6: 0 | Q6: =FALSE() -> FALSE | R6: 0 | S6: 0 | T6: =TRUE() -> TRUE | U6: 1 | V6: 4 | W6: =FALSE() -> FALSE | X6: 0 | Y6: 0 | Z6: =FALSE() -> FALSE | AA6: 0 | AB6: 0 | AC6: =FALSE() -> FALSE | AD6: 0 | AE6: 0 | AF6: =TRUE() -> TRUE | AG6: 1 | AH6: 3 | AI6: =TRUE() -> TRUE | AJ6: 1 | AK6: 4 | AL6: =TRUE() -> TRUE | AM6: 3 | AN6: 10
A7: 004-001 | B7: =TRUE() -> TRUE | C7: 1 | D7: 4 | E7: =TRUE() -> TRUE | F7: 1 | G7: 3 | H7: =FALSE() -> FALSE | I7: 0 | J7: 0 | K7: =FALSE() -> FALSE | L7: 0 | M7: 0 | N7: =FALSE() -> FALSE | O7: 0 | P7: 0 | Q7: =TRUE() -> TRUE | R7: 1 | S7: 2 | T7: =FALSE() -> FALSE | U7: 0 | V7: 0 | W7: =FALSE() -> FALSE | X7: 0 | Y7: 0 | Z7: =FALSE() -> FALSE | AA7: 0 | AB7: 0 | AC7: =FALSE() -> FALSE | AD7: 0 | AE7: 0 | AF7: =FALSE() -> FALSE | AG7: 0 | AH7: 0 | AI7: =FALSE() -> FALSE | AJ7: 0 | AK7: 0 | AL7: =TRUE() -> TRUE | AM7: 1 | AN7: 3
A8: 004-002 | B8: =TRUE() -> TRUE | C8: 2 | D8: 5 | E8: =TRUE() -> TRUE | F8: 2 | G8: 2 | H8: =TRUE() -> TRUE | I8: 1 | J8: 3 | K8: =TRUE() -> TRUE | L8: 3 | M8: 11 | N8: =FALSE() -> FALSE | O8: 0 | P8: 0 | Q8: =TRUE() -> TRUE | R8: 2 | S8: 7 | T8: =TRUE() -> TRUE | U8: 2 | V8: 7 | W8: =TRUE() -> TRUE | X8: 4 | Y8: 15 | Z8: =TRUE() -> TRUE | AA8: 1 | AB8: 2 | AC8: =TRUE() -> TRUE | AD8: 1 | AE8: 1 | AF8: =FALSE() -> FALSE | AG8: 0 | AH8: 0 | AI8: =TRUE() -> TRUE | AJ8: 2 | AK8: 7 | AL8: =TRUE() -> TRUE | AM8: 1 | AN8: 3
A9: 004-003 | B9: =TRUE() -> TRUE | C9: 1 | D9: 1 | E9: =TRUE() -> TRUE | F9: 1 | G9: 3 | H9: =TRUE() -> TRUE | I9: 1 | J9: 3 | K9: =TRUE() -> TRUE | L9: 1 | M9: 4 | N9: =FALSE() -> FALSE | O9: 0 | P9: 0 | Q9: =FALSE() -> FALSE | R9: 0 | S9: 0 | T9: =TRUE() -> TRUE | U9: 1 | V9: 3 | W9: =TRUE() -> TRUE | X9: 1 | Y9: 4 | Z9: =FALSE() -> FALSE | AA9: 0 | AB9: 0 | AC9: =TRUE() -> TRUE | AD9: 1 | AE9: 2 | AF9: =TRUE() -> TRUE | AG9: 1 | AH9: 1 | AI9: =TRUE() -> TRUE | AJ9: 2 | AK9: 7 | AL9: =TRUE() -> TRUE | AM9: 1 | AN9: 4
A10: 004-004 | B10: =FALSE() -> FALSE | C10: 0 | D10: 0 | E10: =FALSE() -> FALSE | F10: 0 | G10: 0 | H10: =FALSE() -> FALSE | I10: 0 | J10: 0 | K10: =FALSE() -> FALSE | L10: 0 | M10: 0 | N10: =FALSE() -> FALSE | O10: 0 | P10: 0 | Q10: =FALSE() -> FALSE | R10: 0 | S10: 0 | T10: =FALSE() -> FALSE | U10: 0 | V10: 0 | W10: =FALSE() -> FALSE | X10: 0 | Y10: 0 | Z10: =TRUE() -> TRUE | AA10: 1 | AB10: 2 | AC10: =FALSE() -> FALSE | AD10: 0 | AE10: 0 | AF10: =FALSE() -> FALSE | AG10: 0 | AH10: 0 | AI10: =FALSE() -> FALSE | AJ10: 0 | AK10: 0 | AL10: =FALSE() -> FALSE | AM10: 0 | AN10: 0
A11: 005-001 | B11: =FALSE() -> FALSE | C11: 0 | D11: 0 | E11: =FALSE() -> FALSE | F11: 0 | G11: 0 | H11: =FALSE() -> FALSE | I11: 0 | J11: 0 | K11: =FALSE() -> FALSE | L11: 0 | M11: 0 | N11: =FALSE() -> FALSE | O11: 0 | P11: 0 | Q11: =FALSE() -> FALSE | R11: 0 | S11: 0 | T11: =FALSE() -> FALSE | U11: 0 | V11: 0 | W11: =FALSE() -> FALSE | X11: 0 | Y11: 0 | Z11: =FALSE() -> FALSE | AA11: 0 | AB11: 0 | AC11: =FALSE() -> FALSE | AD11: 0 | AE11: 0 | AF11: =FALSE() -> FALSE | AG11: 0 | AH11: 0 | AI11: =TRUE() -> TRUE | AJ11: 1 | AK11: 2 | AL11: =FALSE() -> FALSE | AM11: 0 | AN11: 0
A12: 005-002 | B12: =TRUE() -> TRUE | C12: 5 | D12: 19 | E12: =FALSE() -> FALSE | F12: 0 | G12: 0 | H12: =FALSE() -> FALSE | I12: 0 | J12: 0 | K12: =FALSE() -> FALSE | L12: 0 | M12: 0 | N12: =FALSE() -> FALSE | O12: 0 | P12: 0 | Q12: =TRUE() -> TRUE | R12: 1 | S12: 2 | T12: =FALSE() -> FALSE | U12: 0 | V12: 0 | W12: =FALSE() -> FALSE | X12: 0 | Y12: 0 | Z12: =FALSE() -> FALSE | AA12: 0 | AB12: 0 | AC12: =TRUE() -> TRUE | AD12: 1 | AE12: 3 | AF12: =FALSE() -> FALSE | AG12: 0 | AH12: 0 | AI12: =TRUE() -> TRUE | AJ12: 1 | AK12: 2 | AL12: =FALSE() -> FALSE | AM12: 0 | AN12: 0
A13: 006-001 | B13: =TRUE() -> TRUE | C13: 1 | D13: 4 | E13: =FALSE() -> FALSE | F13: 0 | G13: 0 | H13: =FALSE() -> FALSE | I13: 0 | J13: 0 | K13: =FALSE() -> FALSE | L13: 0 | M13: 0 | N13: =TRUE() -> TRUE | O13: 1 | P13: 4 | Q13: =TRUE() -> TRUE | R13: 1 | S13: 1 | T13: =TRUE() -> TRUE | U13: 1 | V13: 4 | W13: =FALSE() -> FALSE | X13: 0 | Y13: 0 | Z13: =FALSE() -> FALSE | AA13: 0 | AB13: 0 | AC13: =FALSE() -> FALSE | AD13: 0 | AE13: 0 | AF13: =TRUE() -> TRUE | AG13: 3 | AH13: 10 | AI13: =FALSE() -> FALSE | AJ13: 0 | AK13: 0 | AL13: =FALSE() -> FALSE | AM13: 0 | AN13: 0
A14: 006-002 | B14: =TRUE() -> TRUE | C14: 1 | D14: 4 | E14: =FALSE() -> FALSE | F14: 0 | G14: 0 | H14: =TRUE() -> TRUE | I14: 2 | J14: 6 | K14: =FALSE() -> FALSE | L14: 0 | M14: 0 | N14: =TRUE() -> TRUE | O14: 1 | P14: 4 | Q14: =FALSE() -> FALSE | R14: 0 | S14: 0 | T14: =FALSE() -> FALSE | U14: 0 | V14: 0 | W14: =TRUE() -> TRUE | X14: 1 | Y14: 4 | Z14: =TRUE() -> TRUE | AA14: 2 | AB14: 5 | AC14: =TRUE() -> TRUE | AD14: 2 | AE14: 8 | AF14: =FALSE() -> FALSE | AG14: 0 | AH14: 0 | AI14: =FALSE() -> FALSE | AJ14: 0 | AK14: 0 | AL14: =FALSE() -> FALSE | AM14: 0 | AN14: 0
A15: 007-001 | B15: =FALSE() -> FALSE | C15: 0 | D15: 0 | E15: =FALSE() -> FALSE | F15: 0 | G15: 0 | H15: =FALSE() -> FALSE | I15: 0 | J15: 0 | K15: =FALSE() -> FALSE | L15: 0 | M15: 0 | N15: =TRUE() -> TRUE | O15: 1 | P15: 3 | Q15: =TRUE() -> TRUE | R15: 1 | S15: 4 | T15: =TRUE() -> TRUE | U15: 1 | V15: 3 | W15: =FALSE() -> FALSE | X15: 0 | Y15: 0 | Z15: =TRUE() -> TRUE | AA15: 1 | AB15: 1 | AC15: =FALSE() -> FALSE | AD15: 0 | AE15: 0 | AF15: =FALSE() -> FALSE | AG15: 0 | AH15: 0 | AI15: =FALSE() -> FALSE | AJ15: 0 | AK15: 0 | AL15: =FALSE() -> FALSE | AM15: 0 | AN15: 0
A16: 007-002 | B16: =FALSE() -> FALSE | C16: 0 | D16: 0 | E16: =FALSE() -> FALSE | F16: 0 | G16: 0 | H16: =FALSE() -> FALSE | I16: 0 | J16: 0 | K16: =FALSE() -> FALSE | L16: 0 | M16: 0 | N16: =FALSE() -> FALSE | O16: 0 | P16: 0 | Q16: =FALSE() -> FALSE | R16: 0 | S16: 0 | T16: =TRUE() -> TRUE | U16: 1 | V16: 2 | W16: =FALSE() -> FALSE | X16: 0 | Y16: 0 | Z16: =FALSE() -> FALSE | AA16: 0 | AB16: 0 | AC16: =FALSE() -> FALSE | AD16: 0 | AE16: 0 | AF16: =FALSE() -> FALSE | AG16: 0 | AH16: 0 | AI16: =FALSE() -> FALSE | AJ16: 0 | AK16: 0 | AL16: =TRUE() -> TRUE | AM16: 1 | AN16: 4
A17: 007-003 | B17: =FALSE() -> FALSE | C17: 0 | D17: 0 | E17: =TRUE() -> TRUE | F17: 1 | G17: 4 | H17: =FALSE() -> FALSE | I17: 0 | J17: 0 | K17: =FALSE() -> FALSE | L17: 0 | M17: 0 | N17: =FALSE() -> FALSE | O17: 0 | P17: 0 | Q17: =FALSE() -> FALSE | R17: 0 | S17: 0 | T17: =FALSE() -> FALSE | U17: 0 | V17: 0 | W17: =FALSE() -> FALSE | X17: 0 | Y17: 0 | Z17: =TRUE() -> TRUE | AA17: 1 | AB17: 4 | AC17: =TRUE() -> TRUE | AD17: 2 | AE17: 5 | AF17: =TRUE() -> TRUE | AG17: 1 | AH17: 4 | AI17: =TRUE() -> TRUE | AJ17: 1 | AK17: 3 | AL17: =TRUE() -> TRUE | AM17: 1 | AN17: 4
A18: 007-004 | B18: =TRUE() -> TRUE | C18: 1 | D18: 4 | E18: =FALSE() -> FALSE | F18: 0 | G18: 0 | H18: =TRUE() -> TRUE | I18: 1 | J18: 2 | K18: =FALSE() -> FALSE | L18: 0 | M18: 0 | N18: =FALSE() -> FALSE | O18: 0 | P18: 0 | Q18: =FALSE() -> FALSE | R18: 0 | S18: 0 | T18: =TRUE() -> TRUE | U18: 1 | V18: 4 | W18: =FALSE() -> FALSE | X18: 0 | Y18: 0 | Z18: =FALSE() -> FALSE | AA18: 0 | AB18: 0 | AC18: =TRUE() -> TRUE | AD18: 2 | AE18: 5 | AF18: =FALSE() -> FALSE | AG18: 0 | AH18: 0 | AI18: =TRUE() -> TRUE | AJ18: 2 | AK18: 8 | AL18: =TRUE() -> TRUE | AM18: 1 | AN18: 3
A19: 007-005 | B19: =TRUE() -> TRUE | C19: 1 | D19: 4 | E19: =FALSE() -> FALSE | F19: 0 | G19: 0 | H19: =TRUE() -> TRUE | I19: 1 | J19: 2 | K19: =TRUE() -> TRUE | L19: 1 | M19: 3 | N19: =TRUE() -> TRUE | O19: 5 | P19: 13 | Q19: =FALSE() -> FALSE | R19: 0 | S19: 0 | T19: =FALSE() -> FALSE | U19: 0 | V19: 0 | W19: =FALSE() -> FALSE | X19: 0 | Y19: 0 | Z19: =TRUE() -> TRUE | AA19: 1 | AB19: 3 | AC19: =FALSE() -> FALSE | AD19: 0 | AE19: 0 | AF19: =FALSE() -> FALSE | AG19: 0 | AH19: 0 | AI19: =TRUE() -> TRUE | AJ19: 1 | AK19: 3 | AL19: =FALSE() -> FALSE | AM19: 0 | AN19: 0
A20: 008-001 | B20: =FALSE() -> FALSE | C20: 0 | D20: 0 | E20: =FALSE() -> FALSE | F20: 0 | G20: 0 | H20: =FALSE() -> FALSE | I20: 0 | J20: 0 | K20: =FALSE() -> FALSE | L20: 0 | M20: 0 | N20: =FALSE() -> FALSE | O20: 0 | P20: 0 | Q20: =FALSE() -> FALSE | R20: 0 | S20: 0 | T20: =FALSE() -> FALSE | U20: 0 | V20: 0 | W20: =FALSE() -> FALSE | X20: 0 | Y20: 0 | Z20: =FALSE() -> FALSE | AA20: 0 | AB20: 0 | AC20: =FALSE() -> FALSE | AD20: 0 | AE20: 0 | AF20: =FALSE() -> FALSE | AG20: 0 | AH20: 0 | AI20: =FALSE() -> FALSE | AJ20: 0 | AK20: 0 | AL20: =FALSE() -> FALSE | AM20: 0 | AN20: 0

Sheet Strategies
A1: ID | B1: Name | C1: Name - German | D1: Description | E1: Description - German
A2: 001-001 | B2: Rehearsal and mnemonic strategies (memorising) | C2: Übungs- und Gedächtnisstrategien (Auswendiglernen) | D2: Statements indicating student-initiated efforts to memorize material by overt or covert practice, e.g., "In preparing for a math test, I keep writing the formula down until I remember it." | E2: Aussagen, die auf von Schülern initiierte Bemühungen hinweisen, sich den Lernstoff durch offenes oder verdecktes Üben einzuprägen, z.B.: 'Wenn ich mich auf eine Matheprüfung vorbereite, schreibe ich die Formel so lange auf, bis ich sie mir einpräge.'
A3: 001-002 | B3: Practice testing | C3: Wissenstest | D3: Statements indicating student-initiated efforts to practice recalling the material by working through questions, e.g. "I use exams from previous years to practice." "I quiz myself using flashcards." | E3: Aussagen, die auf von Schülern initiierte Bemühungen hinweisen, sich den Stoff durch das Durcharbeiten von Fragen einzuprägen, z. B. "Ich verwende Prüfungen aus früheren Jahren zum Üben." "Ich teste mich selbst mithilfe von Karteikarten."
A4: 002-001 | B4: Repetition over time | C4: Wiederholung | D4: Statements indicating student-initiated efforts to review material studied in earlier sessions at later times, e.g., "I review flashcards at regular intervals." | E4: Aussagen, die auf von Schülern initiierte Bemühungen hinweisen, in früheren Sitzungen erlerntes Material zu einem späteren Zeitpunkt zu wiederholen, z. B. "Ich gehe Karteikarten in regelmäßigen Abständen durch."
A5: 003-001 | B5: reviewing previously compiled records, e.g. tests, notes or course material/textbooks | C5: Lesen von bereits erstellten Aufzeichnungen, z. B. Tests, Notizen oder Kursmaterial/Lehrbücher | D5: Statements indicating student-initiated efforts to reread tests, notes, or textbooks to prepare for class or further testing, e.g., "When preparing for a test, I review my notes." | E5: Aussagen, die auf von Studenten initiierte Bemühungen hinweisen, Tests, Notizen oder Lehrbücher zur Vorbereitung auf den Unterricht oder weitere Tests erneut zu lesen, z. B. "Wenn ich mich auf einen Test vorbereite, gehe ich meine Notizen noch einmal durch."
A6: 004-001 | B6: Highlighting and underlining | C6: Hervorheben und Unterstreichen | D6: Statements indicating student-initiated efforts to mark the central points of material to be learned, e.g., "When I read the course text I highlight important parts." | E6: Aussagen, die auf von Studenten initiierte Bemühungen hinweisen, die zentralen Punkte des zu lernenden Materials visuell hervorzuheben, z. B. "Wenn ich den Kurstext lese, markiere ich wichtige Teile."
A7: 004-002 | B7: Organising and transforming | C7: Organisieren und Umstrukturieren | D7: Statements indicating student-initiated overt or covert rearrangement of instructional materials to improve learning, e.g., "I make an outline before I write my paper." "I write a summary in my own words." "I create a mind map, knowledge graph or diagram of the material." | E7: Aussagen, die auf von Studenten initiierte offene oder verdeckte Umgestaltung von Unterrichtsmaterialien hinweisen, um das Lernen zu verbessern, z. B. "Ich erstelle eine Gliederung, bevor ich meine Arbeit schreibe." "Ich schreibe eine Zusammenfassung in meinen eigenen Worten." "Ich erstelle eine Mindmap, ein Wissensdiagramm oder ein Diagramm des Materials."
A8: 004-003 | B8: Keeping records and monitoring | C8: Aufzeichnungen führen | D8: Statements indicating student-initiated efforts to record events or results, e.g., "I took notes of the class discussion." "I kept a list of the words I got wrong." | E8: Aussagen, die auf von Studenten initiierte Bemühungen hinweisen, Ereignisse oder Ergebnisse aufzuzeichnen, z. B. "Ich habe mir Notizen zur Unterrichtsdiskussion gemacht." "Ich habe eine Liste der Wörter geführt, die ich falsch hatte."
A9: 004-004 | B9: Visualisation | C9: Visualisierung | D9: Statements indicating student-initiated efforts to create explanative or organizational drawings to illustrate lesson contents or forming mental images of the material, e.g., "I try to imagine what this would look like." | E9: Aussagen, die auf von Schülern initiierte Bemühungen hinweisen, erklärende oder strukturierende Zeichnungen zu erstellen, um Unterrichtsinhalte zu veranschaulichen oder sich ein Bild vom Material zu machen, z. B. "Ich versuche mir vorzustellen, wie das aussehen würde."
A10: 005-001 | B10: Teaching and preparing to teach | C10: Unterrichten und Unterrichtsvorbereitung | D10: Statements indicating student-initiated efforts to understand material by explaining it to someone else or preparing to do so, e.g., "I try to explain the material to a friend." "I prepare a presentation for my study group." | E10: Aussagen, die auf von Schülern initiierte Bemühungen hinweisen, den Stoff zu verstehen, indem sie ihn jemand anderem erklären oder sich darauf vorbereiten, z. B. "Ich versuche, den Stoff einem Freund zu erklären." "Ich bereite eine Präsentation für meine Lerngruppe vor."
A11: 005-002 | B11: Self Explanation | C11: Selbsterklärung | D11: Statements indicating student-initiated efforts to understand material by verbally or mentally explaining how new information is related to previously learned material, e.g., "I think out loud when I work through a task." | E11: Aussagen, die auf von Schülern initiierte Bemühungen hinweisen, den Stoff zu verstehen, indem sie verbal oder gedanklich erklären, wie neue Informationen mit zuvor gelerntem Stoff zusammenhängen, z. B. "Ich denke laut, wenn ich eine Aufgabe durcharbeite."
A12: 006-001 | B12: goal setting and planning | C12: Lernziele setzen und planen | D12: Statements indicating student setting of educational goals or subgoals and planning for prioritising, sequencing, timing, and completing activities related to those goals, e.g., "First, I start studying two weeks before exams, and I pace myself." "I review the materials and decide what to focus on first." | E12: Aussagen, die darauf hinweisen, dass sich Studierende Lernziele oder Teilziele setzen und die Priorisierung, Reihenfolge, Zeiteinteilung und Erledigung von Aktivitäten planen, die mit diesen Zielen in Zusammenhang stehen, z. B. "Zunächst beginne ich zwei Wochen vor den Prüfungen mit dem Lernen und teile mir mein Tempo ein." "Ich schaue mir die Materialien an und entscheide, worauf ich mich zuerst konzentriere."
... A19: 008-001 | B19: other | C19: Andere | D19: Statements indicating learning behaviour that is initiated by other persons such as teachers or parents, and all unclear verbal responses, e.g., "I just do what the teacher says." | E19: Aussagen über Lernverhalten, das von anderen Personen wie Lehrern oder Eltern initiiert wird, und alle unklaren verbalen Reaktionen, z. B.: 'Ich mache nur, was der Lehrer sagt.'

Sheet Contexts
A1: ID | B1: ID-German | C1: Description | D1: Description - German
A2: 1 | B2: 7 | C2: learning and remembering what was said during in-person or online events | D2: Aufnehmen und Erinnern von Inhalten von Live-Veranstaltungen in Präsenz oder Online
A3: 2 | B3: 8 | C3: reviewing course material at home | D3: Durcharbeiten von Kurstexten
A4: 3 | B4: 9 | C4: writing a scientific paper, such as a term paper/seminar paper, an internship report or a laboratory report | D4: Verfassen einer wissenschaftlichen Arbeit, wie z.B. einer Hausarbeit/Seminararbeit, eines Praktikumsberichts oder Laborberichts
A5: 4 | B5: 10 | C5: completing practice tasks to test understanding of the course material | D5: Bearbeiten von Übungsaufgaben zum Kursmaterial
A6: 5 | B6: 11 | C6: preparing for and taking oral or written exams | D6: Vorbereitung und Ablegen mündlicher oder schriftlicher Prüfungen
A7: 6 | B7: 12 | C7: when poorly motivated to study | D7: Bei geringer Motivation zum Lernen

Sheet P1
B1: Strategies manual coding | C1: Strategies match agent recognised ones | D1: Step executed correctly | E1: Step execution comment | F1: Expected input received | G1: Unexpected input handled successfully | H1: Unexpected input comment | I1: Agent uses appropriate degrees of formality, linguistic register | J1: Agent formality/register comment | K1: Tone of user response from 1 (very negative) - 5 (very positive) | L1: Agent responds to user mood / sentiment | M1: Positive/negative sentiment keywords | N1: speaker | O1: turn | P1: context | Q1: strategy | R1: conversation_step | S1: message_time | T1: message
A2: Totals | C2: =COUNTIF(C7:C100,"y")/(COUNTIF(C7:C100,"y")+COUNTIF(C7:C100,"n")) -> 0.33333333 | D2: =COUNTIF(D7:D100,"y")/(COUNTIF(D7:D100,"y")+COUNTIF(D7:D100,"n")) -> 0.64285714 | F2: =COUNTIF(F7:F100,"y")/(COUNTIF(F7:F100,"y")+COUNTIF(F7:F100,"n")) -> 0.80769231 | G2: =COUNTIF(G7:G100,"y")/(COUNTIF(G7:G100,"y")+COUNTIF(G7:G100,"n")) -> 0.28571429 | I2: =COUNTIF(I7:I100,"y")/(COUNTIF(I7:I100,"y")+COUNTIF(I7:I100,"n")) -> 0.64285714 | K2: =COUNTIF(K7:K100,"1") -> 0 | L2: =COUNTIF(L7:L100,"y")/(COUNTIF(L7:L100,"y")+COUNTIF(L7:L100,"n")) -> 0.53846154 | O2: {=LOOKUP(2,1/(O:O<>""),O:O)} -> 55 | R2: =COUNTIF(R7:R100,"strategy")/2 -> 9 | S2: {=LOOKUP(2,1/(S:S<>""),S:S)-S7} -> 0.028805451
K3: =COUNTIF(K7:K100,"2") -> 3 | R3: =COUNTIF(R7:R100,"frequency")/2 -> 16
K4: =COUNTIF(K7:K100,"3") -> 23 | R4: =CEILING(COUNTIF(R7:R100,"complete")/2,1) -> 2
K5: =COUNTIF(K7:K100,"4") -> 1
K6: =COUNTIF(K7:K100,"5") -> 0
D7: y | I7: y | M7: freue | N7: agent | O7: 1 | R7: intro | S7: 45582.483 | T7: Hallo, vielen Dank, dass du dir Zeit für dieses Gespräch nimmst! Ich freue mich darauf, mehr über deine Lernstrategien und -methoden zu erfahren. Um loszulegen: In welchem Fach strebst du einen Abschluss an?
B8: n/a | F8: y | K8: 3 | N8: user | O8: 2 | R8: intro | S8: 45582.484 | T8: In Psychologie, Bachelor of Science
D9: y | I9: y | M9: freue, gerne | N9: agent | O9: 3 | P9: 9 | R9: strategy | S9: 45582.484 | T9: Hallo! Ich freue mich, dass du dir die Zeit nimmst, um mir von deinen Lernstrategien und -methoden zu erzählen. Ich möchte gerne mehr darüber erfahren, wie du wissenschaftliche Arbeiten wie Hausarbeiten, Seminararbeiten, Praktikumsberichte oder Laborberichte verfasst. Kannst du mir ein Beispiel geben, wie du in einem solchen Lernkontext vorgehst?
B10: 004-002, 007-003 | C10: n | F10: y | K10: 4 | M10: gerne, gut, zufrieden | N10: user | O10: 4 | P10: 9 | R10: strategy | S10: 45582.487 | T10: Ja gerne. Nachdem ich weiß, was die Vision und das Ziel ist, und ich meine wissenschafliche Arbeit durchgeführt habe und un den Bericht verfassen muss, gehe ich so vor, dass ich zunächst das Abstract schreibe. Dadurch weiß ich, ob ich meine Arbeit gut darstellen kann. Anschließend fange ich damit an die ganze Arbeit strukturell aufzubauen und zu entscheiden, welche Kapitel ich brauche. Dann fange ich an mit dem Outlining meiner Arbeit und setze bereits wichtige Tabellen und Bilder in meine Arbeit ein. Darin schreibe ich überall punktuell rein, was ich dem Leser über meine Arbeit berichten möchte. Dieses Outline verfeinere ich immer wieder, bis ich zufrieden bin. Anschließend arbeite ich jeden Punkt aus, und entwickle ganze Sätze. Die Sätze sind noch sehr grob und enthalten fehler. Allerdings schreibe ich zügig und verfeinere die Sprache dann zum Schluss. Final zeige ich Kollegen meine Arbeit und hole mir Feedback dazu ein. Das mache ich immer weiter, bis keine Kritik mehr vorhanden ist. Dann reiche ich meine Arbeit fristgerecht ein.
C11: y | D11: y | I11: n | J11: Ignores instruction not to comment (positively or negatively) on the user's answer | L11: y | M11: großartig | N11: agent | O11: 5 | P11: 9 | Q11: 004-002 | R11: frequency | S11: 45582.487 | T11: Das klingt nach einer sehr strukturierten und effektiven Vorgehensweise! Es ist großartig, dass du das Abstract als ersten Schritt verwendest, um deine Arbeit zu strukturieren und sicherzustellen, dass du deine Ziele erreicht hast. Das Erstellen eines Outlines und das Einsetzen von Tabellen und Bildern hilft dir offensichtlich, deine Arbeit zu visualisieren und zu organisieren. Ich würde sagen, dass du die Lernstrategie "Organisieren und Umstrukturieren" sehr effektiv anwendest. Du strukturierst deine Arbeit, erstellst ein Outline und verfeinerst es kontinuierlich, bis du zufrieden bist. Das ist ein wichtiger Schritt, um sicherzustellen, dass deine Arbeit logisch und leicht verständlich ist. Kannst du mir sagen, wie häufig du diese Lernstrategie in diesem Kontext verwendest? Würdest du sagen, dass du sie selten (1), manchmal (2), oft (3) oder meistens (4) verwendest?
B12: n/a | F12: y | K12: 3 | M12: gut | N12: user | O12: 6 | P12: 9 | Q12: 004-002 | R12: frequency | S12: 45582.488 | T12: Ich verwende sie meistens, also 4. Ich bin bereits eingeübt in dieser Prozedur und habe gute Ergebnisse erzielt. Ich denke, ich werde immer noch etwas besser und würde es beibehalten.
B13: n/a | C13: n | D13: y | E13: Further details requested instead of just frequency | I13: y | L13: y | M13: bemerkenswert | N13: agent | O13: 7 | P13: 9 | Q13: 005-002 | R13: frequency | S13: 45582.488 | T13: Deine Herangehensweise klingt strukturiert und effizient. Du beginnst mit dem Abstract, um den Gesamtüberblick zu behalten, und dann organizational die Arbeit aufzubauen, was dir hilft, den Schreibprozess in kleinere, überschaubare Teile zu unterteilen. Das Setzen von wichtigen Tabellen und Bildern in deine Arbeit aufnimmt, ist ein interessantes Element. Deine Planungscollage mit der Methode des Outlinens, wo du die Arbeit Raeleinheiten und Abschnitte unterteilst, ist eine Untermauerung. Dadurch kannst du deine Gedanken besser organisieren und eine klare Struktur entwickeln. Die Verfeinerung des Outlines und die punktuelle Ergänzung von Informationen hilft dir, deine Gedanken zu präzisieren. Deine Vorgehensweise, die Darlegung der Arbeit mit mit Kollegen zu übersprechen und die Weiterentwicklung basierend deren Feedback umzusetzen, zeigt, dass du offen für Kritik und Verbesserungsvorschläge bist und dir die Qualität deiner Arbeit sehr wichtig ist. Es ist bemerkenswert, wie du deine Zeit planst und deine Arbeit fristgerecht abgibst. Ein wichtiger Aspekt deiner Vorgehensweise ist, dass du deine Ideen, deine Gedanken und deine Ergebnisse in einer klaren und strukturierten Form darlegst. Nun möchte ich genauer wissen, wie du diese Informationen strukturierst und wie du sie in deine Arbeit einbindest. Kannst du mir deine Meinung dazu äußern, wie oft du die Lernstrategie der „Selbsterklärung“ in diesem Prozess anwendest? Glaubst du, diese Strategie ist eine der effizientesten Methoden für so ein Anliegen? Also, im Rahmen von deiner Arbeit, wie häufig nutzt du Selbsterklärung? Mit anderen Worten, würdest du sagen, dass du diese Methode selten (1), manchmal (2), oft (3) oder meistens (4) verwendest?
B14: n/a | F14: y | K14: 3 | M14: (neutral) | N14: user | O14: 8 | P14: 9 | Q14: 005-002 | R14: frequency | S14: 45582.491 | T14: Selbsterkärungen nutze ich auch meistens (4). Häufig mache ich mir dazu vorher Concept Maps am Whiteboard, oder Mindmaps auf dem Papier. Dann gehe ich diese durch Selbstgespräche durch und versuche mich zu hinterfragen, ob ich nicht etwas falsch sehe, oder übersehen habe. Wenn ich garnicht weiter komme, mache ich ein Miro Board auf, was digital ist. Darin mache ich ein sogenanntes Question Storming und sammele lediglich Fragen die mir bezüglich meiner Arbeit in den Sinn kommen. Dafür nehme ich mir mehrere Stunden. Anschließend versuche ich die Fragen zu strukturieren und als Anhaltspunkte zu nutzen, um weitere Recherchen durchzuführen. Das Fragenstellen ist führt meistens zu kritischen Fragen die mir dabei helfen, weitere Erklärungen zu finden. Die Erklärungen schreibe ich dann auch als Postits in das Miro.
